{"version":3,"sources":["js/17-try-catch.js"],"names":["console","log","setTimeout","myVar","error","name","dir"],"mappings":";AAmBA,IACEA,QAAQC,IAAI,uBAEZC,WAAW,WACTC,OACC,KAEHD,WAAW,WACT,IACEC,MACA,MAAOC,GACPJ,QAAQC,IAAIG,EAAMC,MAClBL,QAAQM,IAAIF,GACZJ,QAAQC,IAAI,gCAEb,KAGHE,MAIAH,QAAQC,IAAI,0BAEZ,MAAOG,GACPJ,QAAQC,IAAI,WAIdD,QAAQC,IAAI","file":"17-try-catch.c84e286e.js","sourceRoot":"../src","sourcesContent":["// Обработка ошибок с try...catch\n//  - Синтаксис\n//  - Какие ошибки ловит\n//    - ❌ ошибки парсинга (parsing errors) ( cons a = 9)\n//    - ✅ ошибки выполнения (runtime errors) ( myVar;)\n//  - Ловит только ошибки в синхронном коде\n//    - Как словить ошибку в асинхронном коде\n//  - Объект ошибки\n//    - name\n//    - message\n//    - stack\n//  - Блок catch без объекта ошибки\n\n// try {\n//   попробуй сделать то что находиться тут\n// } catch (error) {\n//   если ошибка тут ее ловим error = описание ошибки\n// }\n\ntry {\n  console.log(\"Внутри try до myVar\");\n  // выполнило\n  setTimeout(() => {\n    myVar;\n  }, 4000);\n  //  - Ловит только ошибки в синхронном коде\n  setTimeout(() => {\n    try {\n      myVar;\n    } catch (error) {\n      console.log(error.name);\n      console.dir(error);\n      console.log(\"Ошибка! в асинхронном коде\");\n    }\n  }, 1000);\n  //    - Как словить ошибку в асинхронном коде\n\n  myVar;\n  // такой переменной нету и скрипт должен падать но оно передает его в catch\n  // cons a = 9\n  // ошибку парсинга не словит и код упадет\n  console.log(\"Внутри try после myVar\");\n  // не выполняем\n} catch (error) {\n  console.log(\"Ошибка!\");\n  // ловим ошибку на 23 строке\n}\n\nconsole.log(\"После try...catch\");\n// скрипт не упал (так как был трай и кеч) по этому все работает дальше\n"]}